<?xml version="1.0"?>
<robot name="eduard">
  <link name="base_link">
    <visual>
      <geometry>
        <mesh filename="package://edu_robot_control/model/mesh/eduard-chassis.dae"/>
      </geometry>
    </visual>
  </link>

  <link name="wheel_front_left">
    <visual>
      <geometry>
        <mesh filename="package://edu_robot_control/model/mesh/offroad-wheel-eduard.dae"/>
      </geometry>
    </visual>
  </link>

  <joint name="base_to_wheel_front_left" type="continuous">
    <origin rpy="1.570796327 0 0" xyz="0.125 0.163 0.02"/>  
    <parent link="base_link"/>
    <child link="wheel_front_left"/>
    <axis xyz="0 0 1"/>
  </joint>

  <link name="wheel_front_right">
    <visual>
      <geometry>
        <mesh filename="package://edu_robot_control/model/mesh/offroad-wheel-eduard.dae"/>
      </geometry>
    </visual>
  </link>

  <joint name="base_to_wheel_front_right" type="continuous">
    <origin rpy="-1.570796327 0 0" xyz="0.125 -0.163 0.02"/>
    <parent link="base_link"/>
    <child link="wheel_front_right"/>
    <axis xyz="0 0 1"/>    
  </joint>

  <link name="wheel_rear_left">
    <visual>
      <geometry>
        <mesh filename="package://edu_robot_control/model/mesh/offroad-wheel-eduard.dae"/>
      </geometry>
    </visual>
  </link>

  <joint name="base_to_wheel_rear_left" type="continuous">
    <origin rpy="1.570796327 0 0" xyz="-0.125 0.163 0.02"/>
    <parent link="base_link"/>
    <child link="wheel_rear_left"/>
    <axis xyz="0 0 1"/>    
  </joint>

  <link name="wheel_rear_right">
    <visual>
      <geometry>
        <mesh filename="package://edu_robot_control/model/mesh/offroad-wheel-eduard.dae"/>
      </geometry>
    </visual>
  </link>

  <joint name="base_to_wheel_rear_right" type="continuous">
    <parent link="base_link"/>
    <child link="wheel_rear_right"/>
    <origin rpy="-1.570796327 0 0" xyz="-0.125 -0.163 0.02"/>
    <axis xyz="0 0 1"/>    
  </joint>
</robot>